{
 "cells": [
  {
   "cell_type": "code",
   "execution_count": 1,
   "metadata": {},
   "outputs": [],
   "source": [
    "import tensorflow as tf\n",
    "import numpy as np\n",
    "from sklearn.model_selection import train_test_split\n",
    "import os\n",
    "import torch\n",
    "from torch import nn\n",
    "from torch.utils.data import DataLoader\n",
    "from torchvision import datasets\n",
    "from torchvision.transforms import ToTensor, Lambda, Compose\n",
    "import matplotlib.pyplot as plt\n",
    "import numpy as np\n",
    "import random\n",
    "import cv2 as cv\n",
    "\n",
    "datasetFileName = \"../master_dataset.npz\"\n"
   ]
  },
  {
   "cell_type": "code",
   "execution_count": 2,
   "metadata": {},
   "outputs": [],
   "source": [
    "tfPath = 'tf/cv_image_tf_97'\n",
    "tfModel = tf.keras.models.load_model(tfPath)\n"
   ]
  },
  {
   "cell_type": "code",
   "execution_count": 3,
   "metadata": {},
   "outputs": [
    {
     "name": "stdout",
     "output_type": "stream",
     "text": [
      "Shape of X [N, C, H, W]:  torch.Size([30, 200, 200, 3])\n",
      "Shape of y:  torch.Size([30]) torch.int64\n",
      "Using cuda device\n"
     ]
    },
    {
     "data": {
      "text/plain": [
       "NeuralNetwork(\n",
       "  (flatten): Flatten(start_dim=1, end_dim=-1)\n",
       "  (linear_relu_stack): Sequential(\n",
       "    (0): Linear(in_features=120000, out_features=512, bias=True)\n",
       "    (1): ReLU()\n",
       "    (2): Linear(in_features=512, out_features=512, bias=True)\n",
       "    (3): ReLU()\n",
       "    (4): Linear(in_features=512, out_features=512, bias=True)\n",
       "    (5): ReLU()\n",
       "    (6): Linear(in_features=512, out_features=9, bias=True)\n",
       "  )\n",
       ")"
      ]
     },
     "execution_count": 3,
     "metadata": {},
     "output_type": "execute_result"
    }
   ],
   "source": [
    "from model_torch import NeuralNetwork\n",
    "trchPath = 'trch/cv_image_torch_93.pth'\n",
    "\n",
    "trchModel = NeuralNetwork()\n",
    "trchModel.load_state_dict(torch.load(trchPath))\n",
    "trchModel.eval()\n"
   ]
  },
  {
   "cell_type": "markdown",
   "metadata": {},
   "source": [
    "loss, acc = newModel.evaluate(testImages, testLabels, verbose=2)\n",
    "print('Restored model, accuracy: {:5.2f}%'.format(100 * acc))\n",
    "\n",
    "newPredictions = newModel.predict(testImages)\n",
    "\n",
    "print(newPredictions.shape)\n",
    "\n",
    "newPredictions[0]"
   ]
  },
  {
   "cell_type": "code",
   "execution_count": 20,
   "metadata": {},
   "outputs": [],
   "source": [
    "img = cv.imread('imgfile/afiq.png')\n",
    "desiredShape = (200, 200, 3)\n",
    "\n",
    "shape = (1, desiredShape[0], desiredShape[1], desiredShape[2])\n",
    "y = np.empty(shape, dtype='uint8')\n",
    "\n",
    "y = cv.resize(img, [200,200], interpolation=cv.INTER_NEAREST)\n",
    "testImage = y"
   ]
  },
  {
   "cell_type": "code",
   "execution_count": 23,
   "metadata": {},
   "outputs": [
    {
     "data": {
      "text/plain": [
       "(200, 200, 3)"
      ]
     },
     "execution_count": 23,
     "metadata": {},
     "output_type": "execute_result"
    }
   ],
   "source": [
    "y.shape"
   ]
  },
  {
   "cell_type": "code",
   "execution_count": 22,
   "metadata": {},
   "outputs": [
    {
     "ename": "ValueError",
     "evalue": "in user code:\n\n    File \"C:\\SDK\\Python39\\lib\\site-packages\\keras\\engine\\training.py\", line 1621, in predict_function  *\n        return step_function(self, iterator)\n    File \"C:\\SDK\\Python39\\lib\\site-packages\\keras\\engine\\training.py\", line 1611, in step_function  **\n        outputs = model.distribute_strategy.run(run_step, args=(data,))\n    File \"C:\\SDK\\Python39\\lib\\site-packages\\keras\\engine\\training.py\", line 1604, in run_step  **\n        outputs = model.predict_step(data)\n    File \"C:\\SDK\\Python39\\lib\\site-packages\\keras\\engine\\training.py\", line 1572, in predict_step\n        return self(x, training=False)\n    File \"C:\\SDK\\Python39\\lib\\site-packages\\keras\\utils\\traceback_utils.py\", line 67, in error_handler\n        raise e.with_traceback(filtered_tb) from None\n    File \"C:\\SDK\\Python39\\lib\\site-packages\\keras\\engine\\input_spec.py\", line 263, in assert_input_compatibility\n        raise ValueError(f'Input {input_index} of layer \"{layer_name}\" is '\n\n    ValueError: Input 0 of layer \"sequential_3\" is incompatible with the layer: expected shape=(None, 200, 200, 3), found shape=(None, None, 3)\n",
     "output_type": "error",
     "traceback": [
      "\u001b[1;31m---------------------------------------------------------------------------\u001b[0m",
      "\u001b[1;31mValueError\u001b[0m                                Traceback (most recent call last)",
      "\u001b[1;32m~\\AppData\\Local\\Temp/ipykernel_17580/2504280248.py\u001b[0m in \u001b[0;36m<module>\u001b[1;34m\u001b[0m\n\u001b[1;32m----> 1\u001b[1;33m \u001b[0mtfPredict\u001b[0m \u001b[1;33m=\u001b[0m \u001b[0mtfModel\u001b[0m\u001b[1;33m.\u001b[0m\u001b[0mpredict\u001b[0m\u001b[1;33m(\u001b[0m\u001b[0mtestImage\u001b[0m\u001b[1;33m)\u001b[0m\u001b[1;33m\u001b[0m\u001b[1;33m\u001b[0m\u001b[0m\n\u001b[0m",
      "\u001b[1;32mC:\\SDK\\Python39\\lib\\site-packages\\keras\\utils\\traceback_utils.py\u001b[0m in \u001b[0;36merror_handler\u001b[1;34m(*args, **kwargs)\u001b[0m\n\u001b[0;32m     65\u001b[0m     \u001b[1;32mexcept\u001b[0m \u001b[0mException\u001b[0m \u001b[1;32mas\u001b[0m \u001b[0me\u001b[0m\u001b[1;33m:\u001b[0m  \u001b[1;31m# pylint: disable=broad-except\u001b[0m\u001b[1;33m\u001b[0m\u001b[1;33m\u001b[0m\u001b[0m\n\u001b[0;32m     66\u001b[0m       \u001b[0mfiltered_tb\u001b[0m \u001b[1;33m=\u001b[0m \u001b[0m_process_traceback_frames\u001b[0m\u001b[1;33m(\u001b[0m\u001b[0me\u001b[0m\u001b[1;33m.\u001b[0m\u001b[0m__traceback__\u001b[0m\u001b[1;33m)\u001b[0m\u001b[1;33m\u001b[0m\u001b[1;33m\u001b[0m\u001b[0m\n\u001b[1;32m---> 67\u001b[1;33m       \u001b[1;32mraise\u001b[0m \u001b[0me\u001b[0m\u001b[1;33m.\u001b[0m\u001b[0mwith_traceback\u001b[0m\u001b[1;33m(\u001b[0m\u001b[0mfiltered_tb\u001b[0m\u001b[1;33m)\u001b[0m \u001b[1;32mfrom\u001b[0m \u001b[1;32mNone\u001b[0m\u001b[1;33m\u001b[0m\u001b[1;33m\u001b[0m\u001b[0m\n\u001b[0m\u001b[0;32m     68\u001b[0m     \u001b[1;32mfinally\u001b[0m\u001b[1;33m:\u001b[0m\u001b[1;33m\u001b[0m\u001b[1;33m\u001b[0m\u001b[0m\n\u001b[0;32m     69\u001b[0m       \u001b[1;32mdel\u001b[0m \u001b[0mfiltered_tb\u001b[0m\u001b[1;33m\u001b[0m\u001b[1;33m\u001b[0m\u001b[0m\n",
      "\u001b[1;32mC:\\SDK\\Python39\\lib\\site-packages\\tensorflow\\python\\framework\\func_graph.py\u001b[0m in \u001b[0;36mautograph_handler\u001b[1;34m(*args, **kwargs)\u001b[0m\n\u001b[0;32m   1127\u001b[0m           \u001b[1;32mexcept\u001b[0m \u001b[0mException\u001b[0m \u001b[1;32mas\u001b[0m \u001b[0me\u001b[0m\u001b[1;33m:\u001b[0m  \u001b[1;31m# pylint:disable=broad-except\u001b[0m\u001b[1;33m\u001b[0m\u001b[1;33m\u001b[0m\u001b[0m\n\u001b[0;32m   1128\u001b[0m             \u001b[1;32mif\u001b[0m \u001b[0mhasattr\u001b[0m\u001b[1;33m(\u001b[0m\u001b[0me\u001b[0m\u001b[1;33m,\u001b[0m \u001b[1;34m\"ag_error_metadata\"\u001b[0m\u001b[1;33m)\u001b[0m\u001b[1;33m:\u001b[0m\u001b[1;33m\u001b[0m\u001b[1;33m\u001b[0m\u001b[0m\n\u001b[1;32m-> 1129\u001b[1;33m               \u001b[1;32mraise\u001b[0m \u001b[0me\u001b[0m\u001b[1;33m.\u001b[0m\u001b[0mag_error_metadata\u001b[0m\u001b[1;33m.\u001b[0m\u001b[0mto_exception\u001b[0m\u001b[1;33m(\u001b[0m\u001b[0me\u001b[0m\u001b[1;33m)\u001b[0m\u001b[1;33m\u001b[0m\u001b[1;33m\u001b[0m\u001b[0m\n\u001b[0m\u001b[0;32m   1130\u001b[0m             \u001b[1;32melse\u001b[0m\u001b[1;33m:\u001b[0m\u001b[1;33m\u001b[0m\u001b[1;33m\u001b[0m\u001b[0m\n\u001b[0;32m   1131\u001b[0m               \u001b[1;32mraise\u001b[0m\u001b[1;33m\u001b[0m\u001b[1;33m\u001b[0m\u001b[0m\n",
      "\u001b[1;31mValueError\u001b[0m: in user code:\n\n    File \"C:\\SDK\\Python39\\lib\\site-packages\\keras\\engine\\training.py\", line 1621, in predict_function  *\n        return step_function(self, iterator)\n    File \"C:\\SDK\\Python39\\lib\\site-packages\\keras\\engine\\training.py\", line 1611, in step_function  **\n        outputs = model.distribute_strategy.run(run_step, args=(data,))\n    File \"C:\\SDK\\Python39\\lib\\site-packages\\keras\\engine\\training.py\", line 1604, in run_step  **\n        outputs = model.predict_step(data)\n    File \"C:\\SDK\\Python39\\lib\\site-packages\\keras\\engine\\training.py\", line 1572, in predict_step\n        return self(x, training=False)\n    File \"C:\\SDK\\Python39\\lib\\site-packages\\keras\\utils\\traceback_utils.py\", line 67, in error_handler\n        raise e.with_traceback(filtered_tb) from None\n    File \"C:\\SDK\\Python39\\lib\\site-packages\\keras\\engine\\input_spec.py\", line 263, in assert_input_compatibility\n        raise ValueError(f'Input {input_index} of layer \"{layer_name}\" is '\n\n    ValueError: Input 0 of layer \"sequential_3\" is incompatible with the layer: expected shape=(None, 200, 200, 3), found shape=(None, None, 3)\n"
     ]
    }
   ],
   "source": [
    "tfPredict = tfModel.predict(testImage)"
   ]
  }
 ],
 "metadata": {
  "interpreter": {
   "hash": "b5572384fec6d310c574784c4ff4f3df12c5eb2938d77a1833302b0cb155924f"
  },
  "kernelspec": {
   "display_name": "Python 3.9.8 64-bit",
   "language": "python",
   "name": "python3"
  },
  "language_info": {
   "codemirror_mode": {
    "name": "ipython",
    "version": 3
   },
   "file_extension": ".py",
   "mimetype": "text/x-python",
   "name": "python",
   "nbconvert_exporter": "python",
   "pygments_lexer": "ipython3",
   "version": "3.9.8"
  },
  "orig_nbformat": 4
 },
 "nbformat": 4,
 "nbformat_minor": 2
}
